Workbook

Sheet Ledger
A1: CONTRIBUTION LEDGER
A2: Funeral Contribution For Our Brother Emmanuel Papa Nii Quaye
A3: Contributions from the group towards the funeral of our brother Emmanuel Papa Nii Quaye. Every amount received is recorded here by the managers so that all members can see it.
A4: Managed by Charles Quaye and Emmanuel Kpakpoe Addo. Members can view this sheet but not change it.
B6: TOTAL COLLECTED | C6: CONTRIBUTORS | D6: ENTRIES
B7: =SUM(Contributions!$C$2:$C$2000) | C7: =SUMPRODUCT((Contributions!$B$2:$B$2000<>"")/COUNTIF(Contributions!$B$2:$B$2000,Contributions!$B$2:$B$2000&"")) | D7: =COUNT(Contributions!$C$2:$C$2000)
B8: in Ghana cedis (GHS) | C8: people who gave | D8: payments recorded
A10: BY MEMBER
A11: # | B11: Member | C11: Payments | D11: Total given
A12: =IF(B12="","",1) | B12: {=IFERROR(INDEX(Contributions!$B$2:$B$2000,MATCH(1,(COUNTIF($B$11:B11,Contributions!$B$2:$B$2000)=0)*(Contributions!$B$2:$B$2000<>""),0)),"")} | C12: =IF(B12="","",COUNTIF(Contributions!$B$2:$B$2000,B12)) | D12: =IF(B12="","",SUMIF(Contributions!$B$2:$B$2000,B12,Contributions!$C$2:$C$2000))
A13: =IF(B13="","",2) | B13: {=IFERROR(INDEX(Contributions!$B$2:$B$2000,MATCH(1,(COUNTIF($B$11:B12,Contributions!$B$2:$B$2000)=0)*(Contributions!$B$2:$B$2000<>""),0)),"")} | C13: =IF(B13="","",COUNTIF(Contributions!$B$2:$B$2000,B13)) | D13: =IF(B13="","",SUMIF(Contributions!$B$2:$B$2000,B13,Contributions!$C$2:$C$2000))
A14: =IF(B14="","",3) | B14: {=IFERROR(INDEX(Contributions!$B$2:$B$2000,MATCH(1,(COUNTIF($B$11:B13,Contributions!$B$2:$B$2000)=0)*(Contributions!$B$2:$B$2000<>""),0)),"")} | C14: =IF(B14="","",COUNTIF(Contributions!$B$2:$B$2000,B14)) | D14: =IF(B14="","",SUMIF(Contributions!$B$2:$B$2000,B14,Contributions!$C$2:$C$2000))
A15: =IF(B15="","",4) | B15: {=IFERROR(INDEX(Contributions!$B$2:$B$2000,MATCH(1,(COUNTIF($B$11:B14,Contributions!$B$2:$B$2000)=0)*(Contributions!$B$2:$B$2000<>""),0)),"")} | C15: =IF(B15="","",COUNTIF(Contributions!$B$2:$B$2000,B15)) | D15: =IF(B15="","",SUMIF(Contributions!$B$2:$B$2000,B15,Contributions!$C$2:$C$2000))
A16: =IF(B16="","",5) | B16: {=IFERROR(INDEX(Contributions!$B$2:$B$2000,MATCH(1,(COUNTIF($B$11:B15,Contributions!$B$2:$B$2000)=0)*(Contributions!$B$2:$B$2000<>""),0)),"")} | C16: =IF(B16="","",COUNTIF(Contributions!$B$2:$B$2000,B16)) | D16: =IF(B16="","",SUMIF(Contributions!$B$2:$B$2000,B16,Contributions!$C$2:$C$2000))
A17: =IF(B17="","",6) | B17: {=IFERROR(INDEX(Contributions!$B$2:$B$2000,MATCH(1,(COUNTIF($B$11:B16,Contributions!$B$2:$B$2000)=0)*(Contributions!$B$2:$B$2000<>""),0)),"")} | C17: =IF(B17="","",COUNTIF(Contributions!$B$2:$B$2000,B17)) | D17: =IF(B17="","",SUMIF(Contributions!$B$2:$B$2000,B17,Contributions!$C$2:$C$2000))
A18: =IF(B18="","",7) | B18: {=IFERROR(INDEX(Contributions!$B$2:$B$2000,MATCH(1,(COUNTIF($B$11:B17,Contributions!$B$2:$B$2000)=0)*(Contributions!$B$2:$B$2000<>""),0)),"")} | C18: =IF(B18="","",COUNTIF(Contributions!$B$2:$B$2000,B18)) | D18: =IF(B18="","",SUMIF(Contributions!$B$2:$B$2000,B18,Contributions!$C$2:$C$2000))
A19: =IF(B19="","",8) | B19: {=IFERROR(INDEX(Contributions!$B$2:$B$2000,MATCH(1,(COUNTIF($B$11:B18,Contributions!$B$2:$B$2000)=0)*(Contributions!$B$2:$B$2000<>""),0)),"")} | C19: =IF(B19="","",COUNTIF(Contributions!$B$2:$B$2000,B19)) | D19: =IF(B19="","",SUMIF(Contributions!$B$2:$B$2000,B19,Contributions!$C$2:$C$2000))
A20: =IF(B20="","",9) | B20: {=IFERROR(INDEX(Contributions!$B$2:$B$2000,MATCH(1,(COUNTIF($B$11:B19,Contributions!$B$2:$B$2000)=0)*(Contributions!$B$2:$B$2000<>""),0)),"")} | C20: =IF(B20="","",COUNTIF(Contributions!$B$2:$B$2000,B20)) | D20: =IF(B20="","",SUMIF(Contributions!$B$2:$B$2000,B20,Contributions!$C$2:$C$2000))
A21: =IF(B21="","",10) | B21: {=IFERROR(INDEX(Contributions!$B$2:$B$2000,MATCH(1,(COUNTIF($B$11:B20,Contributions!$B$2:$B$2000)=0)*(Contributions!$B$2:$B$2000<>""),0)),"")} | C21: =IF(B21="","",COUNTIF(Contributions!$B$2:$B$2000,B21)) | D21: =IF(B21="","",SUMIF(Contributions!$B$2:$B$2000,B21,Contributions!$C$2:$C$2000))
A22: =IF(B22="","",11) | B22: {=IFERROR(INDEX(Contributions!$B$2:$B$2000,MATCH(1,(COUNTIF($B$11:B21,Contributions!$B$2:$B$2000)=0)*(Contributions!$B$2:$B$2000<>""),0)),"")} | C22: =IF(B22="","",COUNTIF(Contributions!$B$2:$B$2000,B22)) | D22: =IF(B22="","",SUMIF(Contributions!$B$2:$B$2000,B22,Contributions!$C$2:$C$2000))
A23: =IF(B23="","",12) | B23: {=IFERROR(INDEX(Contributions!$B$2:$B$2000,MATCH(1,(COUNTIF($B$11:B22,Contributions!$B$2:$B$2000)=0)*(Contributions!$B$2:$B$2000<>""),0)),"")} | C23: =IF(B23="","",COUNTIF(Contributions!$B$2:$B$2000,B23)) | D23: =IF(B23="","",SUMIF(Contributions!$B$2:$B$2000,B23,Contributions!$C$2:$C$2000))
A24: =IF(B24="","",13) | B24: {=IFERROR(INDEX(Contributions!$B$2:$B$2000,MATCH(1,(COUNTIF($B$11:B23,Contributions!$B$2:$B$2000)=0)*(Contributions!$B$2:$B$2000<>""),0)),"")} | C24: =IF(B24="","",COUNTIF(Contributions!$B$2:$B$2000,B24)) | D24: =IF(B24="","",SUMIF(Contributions!$B$2:$B$2000,B24,Contributions!$C$2:$C$2000))
A25: =IF(B25="","",14) | B25: {=IFERROR(INDEX(Contributions!$B$2:$B$2000,MATCH(1,(COUNTIF($B$11:B24,Contributions!$B$2:$B$2000)=0)*(Contributions!$B$2:$B$2000<>""),0)),"")} | C25: =IF(B25="","",COUNTIF(Contributions!$B$2:$B$2000,B25)) | D25: =IF(B25="","",SUMIF(Contributions!$B$2:$B$2000,B25,Contributions!$C$2:$C$2000))
A26: =IF(B26="","",15) | B26: {=IFERROR(INDEX(Contributions!$B$2:$B$2000,MATCH(1,(COUNTIF($B$11:B25,Contributions!$B$2:$B$2000)=0)*(Contributions!$B$2:$B$2000<>""),0)),"")} | C26: =IF(B26="","",COUNTIF(Contributions!$B$2:$B$2000,B26)) | D26: =IF(B26="","",SUMIF(Contributions!$B$2:$B$2000,B26,Contributions!$C$2:$C$2000))
A27: =IF(B27="","",16) | B27: {=IFERROR(INDEX(Contributions!$B$2:$B$2000,MATCH(1,(COUNTIF($B$11:B26,Contributions!$B$2:$B$2000)=0)*(Contributions!$B$2:$B$2000<>""),0)),"")} | C27: =IF(B27="","",COUNTIF(Contributions!$B$2:$B$2000,B27)) | D27: =IF(B27="","",SUMIF(Contributions!$B$2:$B$2000,B27,Contributions!$C$2:$C$2000))
A28: =IF(B28="","",17) | B28: {=IFERROR(INDEX(Contributions!$B$2:$B$2000,MATCH(1,(COUNTIF($B$11:B27,Contributions!$B$2:$B$2000)=0)*(Contributions!$B$2:$B$2000<>""),0)),"")} | C28: =IF(B28="","",COUNTIF(Contributions!$B$2:$B$2000,B28)) | D28: =IF(B28="","",SUMIF(Contributions!$B$2:$B$2000,B28,Contributions!$C$2:$C$2000))
A29: =IF(B29="","",18) | B29: {=IFERROR(INDEX(Contributions!$B$2:$B$2000,MATCH(1,(COUNTIF($B$11:B28,Contributions!$B$2:$B$2000)=0)*(Contributions!$B$2:$B$2000<>""),0)),"")} | C29: =IF(B29="","",COUNTIF(Contributions!$B$2:$B$2000,B29)) | D29: =IF(B29="","",SUMIF(Contributions!$B$2:$B$2000,B29,Contributions!$C$2:$C$2000))
A30: =IF(B30="","",19) | B30: {=IFERROR(INDEX(Contributions!$B$2:$B$2000,MATCH(1,(COUNTIF($B$11:B29,Contributions!$B$2:$B$2000)=0)*(Contributions!$B$2:$B$2000<>""),0)),"")} | C30: =IF(B30="","",COUNTIF(Contributions!$B$2:$B$2000,B30)) | D30: =IF(B30="","",SUMIF(Contributions!$B$2:$B$2000,B30,Contributions!$C$2:$C$2000))
A31: =IF(B31="","",20) | B31: {=IFERROR(INDEX(Contributions!$B$2:$B$2000,MATCH(1,(COUNTIF($B$11:B30,Contributions!$B$2:$B$2000)=0)*(Contributions!$B$2:$B$2000<>""),0)),"")} | C31: =IF(B31="","",COUNTIF(Contributions!$B$2:$B$2000,B31)) | D31: =IF(B31="","",SUMIF(Contributions!$B$2:$B$2000,B31,Contributions!$C$2:$C$2000))
A32: =IF(B32="","",21) | B32: {=IFERROR(INDEX(Contributions!$B$2:$B$2000,MATCH(1,(COUNTIF($B$11:B31,Contributions!$B$2:$B$2000)=0)*(Contributions!$B$2:$B$2000<>""),0)),"")} | C32: =IF(B32="","",COUNTIF(Contributions!$B$2:$B$2000,B32)) | D32: =IF(B32="","",SUMIF(Contributions!$B$2:$B$2000,B32,Contributions!$C$2:$C$2000))
A33: =IF(B33="","",22) | B33: {=IFERROR(INDEX(Contributions!$B$2:$B$2000,MATCH(1,(COUNTIF($B$11:B32,Contributions!$B$2:$B$2000)=0)*(Contributions!$B$2:$B$2000<>""),0)),"")} | C33: =IF(B33="","",COUNTIF(Contributions!$B$2:$B$2000,B33)) | D33: =IF(B33="","",SUMIF(Contributions!$B$2:$B$2000,B33,Contributions!$C$2:$C$2000))
A34: =IF(B34="","",23) | B34: {=IFERROR(INDEX(Contributions!$B$2:$B$2000,MATCH(1,(COUNTIF($B$11:B33,Contributions!$B$2:$B$2000)=0)*(Contributions!$B$2:$B$2000<>""),0)),"")} | C34: =IF(B34="","",COUNTIF(Contributions!$B$2:$B$2000,B34)) | D34: =IF(B34="","",SUMIF(Contributions!$B$2:$B$2000,B34,Contributions!$C$2:$C$2000))
A35: =IF(B35="","",24) | B35: {=IFERROR(INDEX(Contributions!$B$2:$B$2000,MATCH(1,(COUNTIF($B$11:B34,Contributions!$B$2:$B$2000)=0)*(Contributions!$B$2:$B$2000<>""),0)),"")} | C35: =IF(B35="","",COUNTIF(Contributions!$B$2:$B$2000,B35)) | D35: =IF(B35="","",SUMIF(Contributions!$B$2:$B$2000,B35,Contributions!$C$2:$C$2000))
A36: =IF(B36="","",25) | B36: {=IFERROR(INDEX(Contributions!$B$2:$B$2000,MATCH(1,(COUNTIF($B$11:B35,Contributions!$B$2:$B$2000)=0)*(Contributions!$B$2:$B$2000<>""),0)),"")} | C36: =IF(B36="","",COUNTIF(Contributions!$B$2:$B$2000,B36)) | D36: =IF(B36="","",SUMIF(Contributions!$B$2:$B$2000,B36,Contributions!$C$2:$C$2000))
A37: =IF(B37="","",26) | B37: {=IFERROR(INDEX(Contributions!$B$2:$B$2000,MATCH(1,(COUNTIF($B$11:B36,Contributions!$B$2:$B$2000)=0)*(Contributions!$B$2:$B$2000<>""),0)),"")} | C37: =IF(B37="","",COUNTIF(Contributions!$B$2:$B$2000,B37)) | D37: =IF(B37="","",SUMIF(Contributions!$B$2:$B$2000,B37,Contributions!$C$2:$C$2000))
A38: =IF(B38="","",27) | B38: {=IFERROR(INDEX(Contributions!$B$2:$B$2000,MATCH(1,(COUNTIF($B$11:B37,Contributions!$B$2:$B$2000)=0)*(Contributions!$B$2:$B$2000<>""),0)),"")} | C38: =IF(B38="","",COUNTIF(Contributions!$B$2:$B$2000,B38)) | D38: =IF(B38="","",SUMIF(Contributions!$B$2:$B$2000,B38,Contributions!$C$2:$C$2000))
A39: =IF(B39="","",28) | B39: {=IFERROR(INDEX(Contributions!$B$2:$B$2000,MATCH(1,(COUNTIF($B$11:B38,Contributions!$B$2:$B$2000)=0)*(Contributions!$B$2:$B$2000<>""),0)),"")} | C39: =IF(B39="","",COUNTIF(Contributions!$B$2:$B$2000,B39)) | D39: =IF(B39="","",SUMIF(Contributions!$B$2:$B$2000,B39,Contributions!$C$2:$C$2000))
A40: =IF(B40="","",29) | B40: {=IFERROR(INDEX(Contributions!$B$2:$B$2000,MATCH(1,(COUNTIF($B$11:B39,Contributions!$B$2:$B$2000)=0)*(Contributions!$B$2:$B$2000<>""),0)),"")} | C40: =IF(B40="","",COUNTIF(Contributions!$B$2:$B$2000,B40)) | D40: =IF(B40="","",SUMIF(Contributions!$B$2:$B$2000,B40,Contributions!$C$2:$C$2000))
A41: =IF(B41="","",30) | B41: {=IFERROR(INDEX(Contributions!$B$2:$B$2000,MATCH(1,(COUNTIF($B$11:B40,Contributions!$B$2:$B$2000)=0)*(Contributions!$B$2:$B$2000<>""),0)),"")} | C41: =IF(B41="","",COUNTIF(Contributions!$B$2:$B$2000,B41)) | D41: =IF(B41="","",SUMIF(Contributions!$B$2:$B$2000,B41,Contributions!$C$2:$C$2000))
A42: =IF(B42="","",31) | B42: {=IFERROR(INDEX(Contributions!$B$2:$B$2000,MATCH(1,(COUNTIF($B$11:B41,Contributions!$B$2:$B$2000)=0)*(Contributions!$B$2:$B$2000<>""),0)),"")} | C42: =IF(B42="","",COUNTIF(Contributions!$B$2:$B$2000,B42)) | D42: =IF(B42="","",SUMIF(Contributions!$B$2:$B$2000,B42,Contributions!$C$2:$C$2000))
...

Sheet Contributions
A1: Date received | B1: Member name | C1: Amount (GHS) | D1: Note (optional)

Sheet How to use
A1: How this ledger works
A3: MEMBERS: open the Ledger tab. It shows the total collected, how many people have given, and each person's total. Nothing on it can be typed into.
A5: MANAGERS (Charles Quaye, Emmanuel Kpakpoe Addo): open the Contributions tab and type one row per payment received:
A6: 1. Date received – the day the money arrived.
A7: 2. Member name – type the name the same way each time so the person's payments add up together (e.g. always 'Ama Mensah', not sometimes 'Ama').
A8: 3. Amount (GHS) – the amount in cedis, numbers only.
A9: 4. Note – optional. For money from abroad, put the original amount here, e.g. 'USD 50 via Western Union'.
A10: The Ledger tab updates itself the moment a row is saved.
A12: The yellow cells with blue text are the ones to type in. Start on row 2, directly under the headings.
A13: To correct a mistake, edit the row. To remove a payment, clear the whole row.
A14: The Ledger tab lists up to 60 different contributors; payments themselves are unlimited.
